Workbook

Sheet Mode d'emploi
A1: Prix d'Atelier : calcul du prix de revient et du prix de vente
A2: Modèle gratuit pour créateurs fait main : bougies, bijoux, pâtisserie, impression 3D, couture…
A4: À quoi sert ce fichier ?
A5: Il calcule ce que vous coûte réellement chaque produit (matières, perte, emballage, temps, frais fixes),
A6: puis le prix minimum, le prix conseillé et ce qui vous reste par vente en vente directe, sur Etsy,
A7: en dépôt-vente et en vente en gros (avec un prix public conseillé pour la boutique).
A9: Les 4 étapes
A10: 1. Paramètres : votre tarif horaire, vos frais fixes, vos taux de cotisations, la TVA et les frais de chaque canal.
A11: 2. Matières : listez vos fournitures avec le prix et la quantité du lot ; le coût unitaire se calcule seul.
A12: 3. Fiches produit : choisissez les matières dans la liste déroulante, indiquez les quantités, le temps,
A13: le taux de perte et le bénéfice visé. Les prix par canal s'affichent en bas de la fiche.
A14: 4. Synthèse : comparez tous vos produits d'un coup d'œil.
... A47: Aucune macro. Compatible Excel, LibreOffice et Google Sheets (à l'import).

Sheet Paramètres
A1: Paramètres communs à tous les produits
A2: Cellules jaunes : à remplir. Cellules grises ou vertes : calculées automatiquement (protégées).
B3: Paramètre | C3: Valeur | D3: Aide
A4: 1. Votre temps
B5: Méthode du tarif horaire | C5: Déduit | D5: « Saisi » : le tarif ci-dessous. « Déduit » : revenu visé ÷ heures productives.
B6: Tarif horaire saisi (€/h) | C6: 15 | D6: Utilisé si la méthode est « Saisi ».
B7: Revenu net mensuel visé (€) | C7: 1500 | D7: Ce que vous voulez gagner par mois pour votre travail.
B8: Heures productives par mois (h) | C8: 100 | D8: Heures réellement passées à fabriquer (hors administratif, photos, marchés…).
B9: Tarif horaire déduit (€/h) | C9: =IF(Paramètres!$C$8>0,Paramètres!$C$7/Paramètres!$C$8,0) -> 15 | D9: =IF(AND(Paramètres!$C$5="Déduit",N(Paramètres!$C$8)=0),"ATTENTION : heures productives manquantes, le tarif horaire tombe à 0 € et vos prix sont trop bas.","")
B10: Tarif horaire retenu (€/h) | C10: =IF(Paramètres!$C$5="Déduit",Paramètres!$C$9,Paramètres!$C$6) -> 15
A11: 2. Frais fixes
B12: Frais fixes mensuels (€) | C12: 60 | D12: Site, stand, matériel, assurance, banque, abonnements…
B13: Produits vendus par mois | C13: 40 | D13: Nombre moyen de produits vendus par mois, tous produits confondus.
B14: Part de frais fixes par produit (€) | C14: =IF(Paramètres!$C$13>0,Paramètres!$C$12/Paramètres!$C$13,0) -> 1.5 | D14: =IF(AND(N(Paramètres!$C$12)>0,N(Paramètres!$C$13)=0),"ATTENTION : nombre de produits vendus par mois manquant, les frais fixes ne sont pas comptés.","")
A15: 3. Cotisations et TVA (à vérifier et à saisir par vous)
B16: Taux de cotisations sociales (% du chiffre d'affaires) | C16: 0.123 | D16: 12,3 % : vente de vos créations en micro-entreprise, 2026 (Urssaf, vérifié le 25/09/2026). 21,2 % pour les prestations artisanales ; + CFP, versement libératoire… Calculé sur prix + livraison facturée, frais Etsy non déduits.
B17: Facturez-vous la TVA (hors franchise en base) ? | C17: Non | D17: « Non » = franchise en base de TVA : « TVA non applicable, art. 293 B du CGI ».
B18: Taux de TVA si vous la facturez | C18: 0.2 | D18: Utilisé seulement si la réponse est « Oui ».
B19: Taux de TVA appliqué | C19: =IF(Paramètres!$C$17="Oui",Paramètres!$C$18,0) -> 0
B20: Part du prix TTC qui reste après TVA et cotisations | C20: =(1-Paramètres!$C$16)/(1+Paramètres!$C$19) -> 0.877 | D20: Calcul : (1 − cotisations) ÷ (1 + TVA)
A21: 4. Vente directe (marchés, atelier, site perso)
B22: Frais de paiement (% du prix) | C22: 0 | D22: Ex. terminal de paiement : environ 1,75 %.
B23: Frais de paiement fixes par vente (€) | C23: 0 | D23: Laissez 0 si vous n'en avez pas.
A24: 5. Etsy (cellules VIDES : à remplir avec les frais de votre relevé Etsy, hors TVA ; page officielle : etsy.com/fr/legal/fees)
B25: Frais de mise en vente (USD par vente) | D25: À remplir. Exemple du 25/09/2026 (non vérifié depuis) : 0,20 $ par annonce.
B26: Taux de conversion : 1 USD = … EUR | D26: À remplir (valeur d'un dollar en euros). Exemple du 25/09/2026 (cours BCE) : 0,8770 €.
B27: Frais de transaction (% prix + livraison) | D27: À remplir. Exemple du 25/09/2026 (non vérifié depuis) : 6,5 % du prix + livraison.
B28: Frais de traitement du paiement (%) | D28: À remplir. Exemple du 25/09/2026 (non vérifié depuis) : 4 % du total de la commande, livraison comprise.
B29: Frais de traitement du paiement fixes (€) | D29: À remplir. Exemple du 25/09/2026 (non vérifié depuis) : 0,30 € par commande.
B30: Frais réglementaires (%) | D30: À remplir : ce pourcentage dépend du pays de la boutique. Exemple du 25/09/2026 pour la France (non vérifié depuis) : 1,14 %.
B31: Annonce dans une autre devise que l'euro ? | C31: Non | D31: « Non » : aucun frais de conversion pour une annonce en euros sur un compte en euros.
B32: Frais de conversion de devise (%) | D32: À remplir seulement si l'annonce n'est pas en euros. Exemple du 25/09/2026 (non vérifié depuis) : 2,5 % du prix + livraison.
B33: TVA facturée par Etsy sur ses frais | D33: Regardez votre relevé Etsy : s'il comporte de la TVA sur les frais, saisissez son taux ici (vide = 0).
B34: Total des frais Etsy en % (TVA sur frais incluse) | C34: =IF(OR(COUNT(Paramètres!$C$27,Paramètres!$C$28,Paramètres!$C$30)<3,AND(Paramètres!$C$31="Oui",COUNT(Paramètres!$C$32)<1)),"À renseigner",(Paramètres!$C$27+Paramètres!$C$28+Paramètres!$C$30+IF(Paramètres!$C$31="Oui",Paramètres!$C$32,0))*(1+N(Paramètres!$C$33))) -> À renseigner | D34: S'applique au prix TTC de l'article + livraison facturée. « À renseigner » tant que les frais Etsy ci-dessus sont vides : aucun prix Etsy n'est calculé avec des frais vides.
B35: Total des frais Etsy fixes par vente (€, TVA incluse) | C35: =IF(COUNT(Paramètres!$C$29,Paramètres!$C$25,Paramètres!$C$26)<3,"À renseigner",(Paramètres!$C$29+Paramètres!$C$25*Paramètres!$C$26)*(1+N(Paramètres!$C$33))) -> À renseigner
A36: 6. Dépôt-vente
B37: Commission du dépôt-vente (% du prix TTC) | C37: 0.3 | D37: 30 % : valeur typique (source secondaire, 2026), de 25 à 50 % selon la boutique.
A38: 7. Vente en gros (prix public conseillé = votre prix conseillé en vente directe)
B39: Coefficient boutique (prix public TTC ÷ prix de gros HT) | C39: 2.2 | D39: Prix de gros HT = prix public TTC ÷ coefficient. 2 à 2,5 selon la boutique (source secondaire, à vérifier).
B41: =IF(Paramètres!$C$17="Oui","Vos prix calculés sont TTC (TVA incluse).","Mention à porter sur vos factures : « TVA non applicable, art. 293 B du CGI »") -> Mention à porter sur vos factures : « TVA non applicable, art. 293 B du CGI »
...

Sheet Matières
A1: Bibliothèque de matières, emballages et consommables
A2: Une ligne par fourniture achetée en lot. Le coût unitaire est calculé : prix du lot ÷ quantité du lot. Les noms apparaissent ensuite dans les listes déroulantes des fiches produit (noms uniques).
A4: Nom (unique) | B4: Prix du lot (€) | C4: Quantité du lot | D4: Unité | E4: Coût unitaire (€) | F4: Fournisseur / note
A5: Cire de soja | B5: 9 | C5: 1000 | D5: g | E5: =IF(AND(ISNUMBER(B5),ISNUMBER(C5)),IF(C5>0,B5/C5,""),"") -> 0.009 | F5: 9 €/kg port compris (estimé ; 7,99 €/kg par 1 kg chez Smellingood)
A6: Parfum pour bougie | B6: 80 | C6: 1000 | D6: g | E6: =IF(AND(ISNUMBER(B6),ISNUMBER(C6)),IF(C6>0,B6/C6,""),"") -> 0.08 | F6: 80 €/kg (estimé ; 82 à 150 €/L chez Smellingood). 8 % du poids de cire
A7: Mèche coton | B7: 6.29 | C7: 50 | D7: pièce | E7: =IF(AND(ISNUMBER(B7),ISNUMBER(C7)),IF(C7>0,B7/C7,""),"") -> 0.1258 | F7: Lot de 50 (Smellingood)
A8: Pot en verre 200 ml | B8: 11.49 | C8: 6 | D8: pièce | E8: =IF(AND(ISNUMBER(B8),ISNUMBER(C8)),IF(C8>0,B8/C8,""),"") -> 1.915 | F8: Lot de 6 (Smellingood)
A9: Étiquette (dont CLP) | B9: 0.12 | C9: 1 | D9: pièce | E9: =IF(AND(ISNUMBER(B9),ISNUMBER(C9)),IF(C9>0,B9/C9,""),"") -> 0.12 | F9: Source secondaire, 0,05 à 0,40 €
A10: Emballage d'expédition | B10: 0.8 | C10: 1 | D10: pièce | E10: =IF(AND(ISNUMBER(B10),ISNUMBER(C10)),IF(C10>0,B10/C10,""),"") -> 0.8 | F10: Option (source secondaire)
A11: Chaîne acier inox forçat 1,9 mm | B11: 0.9 | C11: 100 | D11: cm | E11: =IF(AND(ISNUMBER(B11),ISNUMBER(C11)),IF(C11>0,B11/C11,""),"") -> 0.009 | F11: 1 m (Perles & Co)
A12: Fermoir mousqueton acier inox 13 mm | B12: 18.5 | C12: 100 | D12: pièce | E12: =IF(AND(ISNUMBER(B12),ISNUMBER(C12)),IF(C12>0,B12/C12,""),"") -> 0.185 | F12: Lot de 100 (Perles & Co)
A13: Anneaux ouverts acier inox 5 mm | B13: 1.5 | C13: 100 | D13: pièce | E13: =IF(AND(ISNUMBER(B13),ISNUMBER(C13)),IF(C13>0,B13/C13,""),"") -> 0.015 | F13: Lot de 100 (Perles & Co)
A14: Perles Miyuki Delica 11/0 | B14: 3.2 | C14: 8 | D14: g | E14: =IF(AND(ISNUMBER(B14),ISNUMBER(C14)),IF(C14>0,B14/C14,""),"") -> 0.4 | F14: Sachet de 8 g (Perles & Co, 3,20 à 5,60 €)
A15: Pochette et carte bijou | B15: 0.5 | C15: 1 | D15: pièce | E15: =IF(AND(ISNUMBER(B15),ISNUMBER(C15)),IF(C15>0,B15/C15,""),"") -> 0.5 | F15: Estimé
A16: Filament PLA | B16: 20 | C16: 1000 | D16: g | E16: =IF(AND(ISNUMBER(B16),ISNUMBER(C16)),IF(C16>0,B16/C16,""),"") -> 0.02 | F16: Bobine de 1 kg (11,04 à 24,99 € ; Bambu Lab, Prusa)
... A20: Papier de soie | B20: 6 | C20: 100 | D20: feuille | E20: =IF(AND(ISNUMBER(B20),ISNUMBER(C20)),IF(C20>0,B20/C20,""),"") -> 0.06 | F20: Exemple (hypothèse)
E21: =IF(AND(ISNUMBER(B21),ISNUMBER(C21)),IF(C21>0,B21/C21,""),"")
E22: =IF(AND(ISNUMBER(B22),ISNUMBER(C22)),IF(C22>0,B22/C22,""),"")
E23: =IF(AND(ISNUMBER(B23),ISNUMBER(C23)),IF(C23>0,B23/C23,""),"")
E24: =IF(AND(ISNUMBER(B24),ISNUMBER(C24)),IF(C24>0,B24/C24,""),"")
E25: =IF(AND(ISNUMBER(B25),ISNUMBER(C25)),IF(C25>0,B25/C25,""),"")
E26: =IF(AND(ISNUMBER(B26),ISNUMBER(C26)),IF(C26>0,B26/C26,""),"")
E27: =IF(AND(ISNUMBER(B27),ISNUMBER(C27)),IF(C27>0,B27/C27,""),"")
E28: =IF(AND(ISNUMBER(B28),ISNUMBER(C28)),IF(C28>0,B28/C28,""),"")
E29: =IF(AND(ISNUMBER(B29),ISNUMBER(C29)),IF(C29>0,B29/C29,""),"")
E30: =IF(AND(ISNUMBER(B30),ISNUMBER(C30)),IF(C30>0,B30/C30,""),"")
E31: =IF(AND(ISNUMBER(B31),ISNUMBER(C31)),IF(C31>0,B31/C31,""),"")
E32: =IF(AND(ISNUMBER(B32),ISNUMBER(C32)),IF(C32>0,B32/C32,""),"")
... E104: =IF(AND(ISNUMBER(B104),ISNUMBER(C104)),IF(C104>0,B104/C104,""),"")

Sheet Fiche 1
A1: ="Fiche 1 : "&IF(B3="","(produit à nommer)",B3) -> Fiche 1 : Bougie parfumée en pot 200 ml
A3: Nom du produit | B3: Bougie parfumée en pot 200 ml
A4: Bénéfice visé (% du coût de revient) | B4: 0.3 | C4: Coefficient équivalent = 1 + % : | E4: =1+B4 -> 1.3
A5: Taux de perte ou d'échec (sur les matières) | B5: 0.04 | C5: Matières ÷ (1 − perte). Strictement inférieur à 100 %.
A6: Temps de fabrication par produit (minutes) | B6: 20 | C6: Multiplié par le tarif horaire des Paramètres.
A7: Livraison facturée au client (Etsy, €) | B7: 5 | C7: Payé par l'acheteur pour la livraison (soumis aux frais Etsy et aux cotisations).
A8: Coût d'envoi réel (Etsy, €) | B8: 4.6 | C8: Ce que l'envoi vous coûte réellement (timbre, transporteur).
A10: Matières utilisées (choisissez dans la liste, issue de l'onglet Matières)
A11: Matière | B11: Unité | C11: Coût unitaire | D11: Quantité utilisée | E11: Coût
A12: Cire de soja | B12: =IF(A12="","",IFERROR(INDEX(Matières!$D$5:$D$104,MATCH(A12,Matières!$A$5:$A$104,0)),"introuvable")) -> g | C12: =IF(A12="","",IFERROR(INDEX(Matières!$E$5:$E$104,MATCH(A12,Matières!$A$5:$A$104,0)),"introuvable")) -> 0.009 | D12: 180 | E12: =IF(AND(ISNUMBER(C12),ISNUMBER(D12)),C12*D12,0) -> 1.62
A13: Parfum pour bougie | B13: =IF(A13="","",IFERROR(INDEX(Matières!$D$5:$D$104,MATCH(A13,Matières!$A$5:$A$104,0)),"introuvable")) -> g | C13: =IF(A13="","",IFERROR(INDEX(Matières!$E$5:$E$104,MATCH(A13,Matières!$A$5:$A$104,0)),"introuvable")) -> 0.08 | D13: 14.4 | E13: =IF(AND(ISNUMBER(C13),ISNUMBER(D13)),C13*D13,0) -> 1.152
A14: Mèche coton | B14: =IF(A14="","",IFERROR(INDEX(Matières!$D$5:$D$104,MATCH(A14,Matières!$A$5:$A$104,0)),"introuvable")) -> pièce | C14: =IF(A14="","",IFERROR(INDEX(Matières!$E$5:$E$104,MATCH(A14,Matières!$A$5:$A$104,0)),"introuvable")) -> 0.1258 | D14: 1 | E14: =IF(AND(ISNUMBER(C14),ISNUMBER(D14)),C14*D14,0) -> 0.1258
A15: Pot en verre 200 ml | B15: =IF(A15="","",IFERROR(INDEX(Matières!$D$5:$D$104,MATCH(A15,Matières!$A$5:$A$104,0)),"introuvable")) -> pièce | C15: =IF(A15="","",IFERROR(INDEX(Matières!$E$5:$E$104,MATCH(A15,Matières!$A$5:$A$104,0)),"introuvable")) -> 1.915 | D15: 1 | E15: =IF(AND(ISNUMBER(C15),ISNUMBER(D15)),C15*D15,0) -> 1.915
A16: Étiquette (dont CLP) | B16: =IF(A16="","",IFERROR(INDEX(Matières!$D$5:$D$104,MATCH(A16,Matières!$A$5:$A$104,0)),"introuvable")) -> pièce | C16: =IF(A16="","",IFERROR(INDEX(Matières!$E$5:$E$104,MATCH(A16,Matières!$A$5:$A$104,0)),"introuvable")) -> 0.12 | D16: 1 | E16: =IF(AND(ISNUMBER(C16),ISNUMBER(D16)),C16*D16,0) -> 0.12
B17: =IF(A17="","",IFERROR(INDEX(Matières!$D$5:$D$104,MATCH(A17,Matières!$A$5:$A$104,0)),"introuvable")) | C17: =IF(A17="","",IFERROR(INDEX(Matières!$E$5:$E$104,MATCH(A17,Matières!$A$5:$A$104,0)),"introuvable")) | E17: =IF(AND(ISNUMBER(C17),ISNUMBER(D17)),C17*D17,0) -> 0
B18: =IF(A18="","",IFERROR(INDEX(Matières!$D$5:$D$104,MATCH(A18,Matières!$A$5:$A$104,0)),"introuvable")) | C18: =IF(A18="","",IFERROR(INDEX(Matières!$E$5:$E$104,MATCH(A18,Matières!$A$5:$A$104,0)),"introuvable")) | E18: =IF(AND(ISNUMBER(C18),ISNUMBER(D18)),C18*D18,0) -> 0
B19: =IF(A19="","",IFERROR(INDEX(Matières!$D$5:$D$104,MATCH(A19,Matières!$A$5:$A$104,0)),"introuvable")) | C19: =IF(A19="","",IFERROR(INDEX(Matières!$E$5:$E$104,MATCH(A19,Matières!$A$5:$A$104,0)),"introuvable")) | E19: =IF(AND(ISNUMBER(C19),ISNUMBER(D19)),C19*D19,0) -> 0
B20: =IF(A20="","",IFERROR(INDEX(Matières!$D$5:$D$104,MATCH(A20,Matières!$A$5:$A$104,0)),"introuvable")) | C20: =IF(A20="","",IFERROR(INDEX(Matières!$E$5:$E$104,MATCH(A20,Matières!$A$5:$A$104,0)),"introuvable")) | E20: =IF(AND(ISNUMBER(C20),ISNUMBER(D20)),C20*D20,0) -> 0
B21: =IF(A21="","",IFERROR(INDEX(Matières!$D$5:$D$104,MATCH(A21,Matières!$A$5:$A$104,0)),"introuvable")) | C21: =IF(A21="","",IFERROR(INDEX(Matières!$E$5:$E$104,MATCH(A21,Matières!$A$5:$A$104,0)),"introuvable")) | E21: =IF(AND(ISNUMBER(C21),ISNUMBER(D21)),C21*D21,0) -> 0
A22: Total matières (avant perte) | E22: =SUM(E12:E21) -> 4.9328
A23: =IF(SUMPRODUCT((A12:A21<>"")*(1-ISNUMBER(C12:C21)))>0,"ATTENTION : une ligne n'a pas de coût unitaire (onglet Matières : prix et quantité du lot, ou nom modifié). Elle compte pour 0 €.","")
A24: Emballage et consommables
A25: Emballage / consommable | B25: Unité | C25: Coût unitaire | D25: Quantité utilisée | E25: Coût
B26: =IF(A26="","",IFERROR(INDEX(Matières!$D$5:$D$104,MATCH(A26,Matières!$A$5:$A$104,0)),"introuvable")) | C26: =IF(A26="","",IFERROR(INDEX(Matières!$E$5:$E$104,MATCH(A26,Matières!$A$5:$A$104,0)),"introuvable")) | E26: =IF(AND(ISNUMBER(C26),ISNUMBER(D26)),C26*D26,0) -> 0
B27: =IF(A27="","",IFERROR(INDEX(Matières!$D$5:$D$104,MATCH(A27,Matières!$A$5:$A$104,0)),"introuvable")) | C27: =IF(A27="","",IFERROR(INDEX(Matières!$E$5:$E$104,MATCH(A27,Matières!$A$5:$A$104,0)),"introuvable")) | E27: =IF(AND(ISNUMBER(C27),ISNUMBER(D27)),C27*D27,0) -> 0
B28: =IF(A28="","",IFERROR(INDEX(Matières!$D$5:$D$104,MATCH(A28,Matières!$A$5:$A$104,0)),"introuvable")) | C28: =IF(A28="","",IFERROR(INDEX(Matières!$E$5:$E$104,MATCH(A28,Matières!$A$5:$A$104,0)),"introuvable")) | E28: =IF(AND(ISNUMBER(C28),ISNUMBER(D28)),C28*D28,0) -> 0
B29: =IF(A29="","",IFERROR(INDEX(Matières!$D$5:$D$104,MATCH(A29,Matières!$A$5:$A$104,0)),"introuvable")) | C29: =IF(A29="","",IFERROR(INDEX(Matières!$E$5:$E$104,MATCH(A29,Matières!$A$5:$A$104,0)),"introuvable")) | E29: =IF(AND(ISNUMBER(C29),ISNUMBER(D29)),C29*D29,0) -> 0
B30: =IF(A30="","",IFERROR(INDEX(Matières!$D$5:$D$104,MATCH(A30,Matières!$A$5:$A$104,0)),"introuvable")) | C30: =IF(A30="","",IFERROR(INDEX(Matières!$E$5:$E$104,MATCH(A30,Matières!$A$5:$A$104,0)),"introuvable")) | E30: =IF(AND(ISNUMBER(C30),ISNUMBER(D30)),C30*D30,0) -> 0
A31: Total emballage | E31: =SUM(E26:E30) -> 0
A32: =IF(SUMPRODUCT((A26:A30<>"")*(1-ISNUMBER(C26:C30)))>0,"ATTENTION : une ligne n'a pas de coût unitaire (onglet Matières : prix et quantité du lot, ou nom modifié). Elle compte pour 0 €.","")
A33: Coût de revient par produit
A34: Matières, perte incluse | B34: =IF(B5<1,E22/(1-B5),E22) -> 5.1383333 | C34: Calcul : total matières ÷ (1 − perte)
A35: Emballage et consommables | B35: =E31 -> 0
A36: Main-d'œuvre | B36: =IF(ISNUMBER(B6),B6/60*Paramètres!$C$10,0) -> 5 | C36: Calcul : minutes ÷ 60 × tarif horaire
A37: Part des frais fixes | B37: =Paramètres!$C$14 -> 1.5 | C37: Calcul : frais fixes mensuels ÷ produits vendus par mois
A38: COÛT DE REVIENT | B38: =SUM(B34:B37) -> 11.638333 | C38: Ce que vous coûte un produit, votre temps compris.
A39: Bénéfice visé | B39: =B38*B4 -> 3.4915 | C39: Calcul : coût de revient × bénéfice visé %
A40: NET VISÉ PAR VENTE | B40: =B38+B39 -> 15.129833 | C40: Ce qui doit vous rester après frais, commissions, TVA et cotisations.
A42: Prix par canal de vente (TTC si vous facturez la TVA ; prix de gros : HT)
B43: Vente directe | C43: Etsy | D43: Dépôt-vente | E43: Gros (HT)
...

Sheet Fiche 2
A1: ="Fiche 2 : "&IF(B3="","(produit à nommer)",B3) -> Fiche 2 : Bracelet chaîne et perles
A3: Nom du produit | B3: Bracelet chaîne et perles
A4: Bénéfice visé (% du coût de revient) | B4: 0.4 | C4: Coefficient équivalent = 1 + % : | E4: =1+B4 -> 1.4
A5: Taux de perte ou d'échec (sur les matières) | B5: 0.03 | C5: Matières ÷ (1 − perte). Strictement inférieur à 100 %.
A6: Temps de fabrication par produit (minutes) | B6: 30 | C6: Multiplié par le tarif horaire des Paramètres.
A7: Livraison facturée au client (Etsy, €) | B7: 0 | C7: Payé par l'acheteur pour la livraison (soumis aux frais Etsy et aux cotisations).
A8: Coût d'envoi réel (Etsy, €) | B8: 0 | C8: Ce que l'envoi vous coûte réellement (timbre, transporteur).
A10: Matières utilisées (choisissez dans la liste, issue de l'onglet Matières)
A11: Matière | B11: Unité | C11: Coût unitaire | D11: Quantité utilisée | E11: Coût
A12: Chaîne acier inox forçat 1,9 mm | B12: =IF(A12="","",IFERROR(INDEX(Matières!$D$5:$D$104,MATCH(A12,Matières!$A$5:$A$104,0)),"introuvable")) -> cm | C12: =IF(A12="","",IFERROR(INDEX(Matières!$E$5:$E$104,MATCH(A12,Matières!$A$5:$A$104,0)),"introuvable")) -> 0.009 | D12: 18 | E12: =IF(AND(ISNUMBER(C12),ISNUMBER(D12)),C12*D12,0) -> 0.162
A13: Fermoir mousqueton acier inox 13 mm | B13: =IF(A13="","",IFERROR(INDEX(Matières!$D$5:$D$104,MATCH(A13,Matières!$A$5:$A$104,0)),"introuvable")) -> pièce | C13: =IF(A13="","",IFERROR(INDEX(Matières!$E$5:$E$104,MATCH(A13,Matières!$A$5:$A$104,0)),"introuvable")) -> 0.185 | D13: 1 | E13: =IF(AND(ISNUMBER(C13),ISNUMBER(D13)),C13*D13,0) -> 0.185
A14: Anneaux ouverts acier inox 5 mm | B14: =IF(A14="","",IFERROR(INDEX(Matières!$D$5:$D$104,MATCH(A14,Matières!$A$5:$A$104,0)),"introuvable")) -> pièce | C14: =IF(A14="","",IFERROR(INDEX(Matières!$E$5:$E$104,MATCH(A14,Matières!$A$5:$A$104,0)),"introuvable")) -> 0.015 | D14: 2 | E14: =IF(AND(ISNUMBER(C14),ISNUMBER(D14)),C14*D14,0) -> 0.03
A15: Perles Miyuki Delica 11/0 | B15: =IF(A15="","",IFERROR(INDEX(Matières!$D$5:$D$104,MATCH(A15,Matières!$A$5:$A$104,0)),"introuvable")) -> g | C15: =IF(A15="","",IFERROR(INDEX(Matières!$E$5:$E$104,MATCH(A15,Matières!$A$5:$A$104,0)),"introuvable")) -> 0.4 | D15: 2 | E15: =IF(AND(ISNUMBER(C15),ISNUMBER(D15)),C15*D15,0) -> 0.8
B16: =IF(A16="","",IFERROR(INDEX(Matières!$D$5:$D$104,MATCH(A16,Matières!$A$5:$A$104,0)),"introuvable")) | C16: =IF(A16="","",IFERROR(INDEX(Matières!$E$5:$E$104,MATCH(A16,Matières!$A$5:$A$104,0)),"introuvable")) | E16: =IF(AND(ISNUMBER(C16),ISNUMBER(D16)),C16*D16,0) -> 0
B17: =IF(A17="","",IFERROR(INDEX(Matières!$D$5:$D$104,MATCH(A17,Matières!$A$5:$A$104,0)),"introuvable")) | C17: =IF(A17="","",IFERROR(INDEX(Matières!$E$5:$E$104,MATCH(A17,Matières!$A$5:$A$104,0)),"introuvable")) | E17: =IF(AND(ISNUMBER(C17),ISNUMBER(D17)),C17*D17,0) -> 0
B18: =IF(A18="","",IFERROR(INDEX(Matières!$D$5:$D$104,MATCH(A18,Matières!$A$5:$A$104,0)),"introuvable")) | C18: =IF(A18="","",IFERROR(INDEX(Matières!$E$5:$E$104,MATCH(A18,Matières!$A$5:$A$104,0)),"introuvable")) | E18: =IF(AND(ISNUMBER(C18),ISNUMBER(D18)),C18*D18,0) -> 0
B19: =IF(A19="","",IFERROR(INDEX(Matières!$D$5:$D$104,MATCH(A19,Matières!$A$5:$A$104,0)),"introuvable")) | C19: =IF(A19="","",IFERROR(INDEX(Matières!$E$5:$E$104,MATCH(A19,Matières!$A$5:$A$104,0)),"introuvable")) | E19: =IF(AND(ISNUMBER(C19),ISNUMBER(D19)),C19*D19,0) -> 0
B20: =IF(A20="","",IFERROR(INDEX(Matières!$D$5:$D$104,MATCH(A20,Matières!$A$5:$A$104,0)),"introuvable")) | C20: =IF(A20="","",IFERROR(INDEX(Matières!$E$5:$E$104,MATCH(A20,Matières!$A$5:$A$104,0)),"introuvable")) | E20: =IF(AND(ISNUMBER(C20),ISNUMBER(D20)),C20*D20,0) -> 0
B21: =IF(A21="","",IFERROR(INDEX(Matières!$D$5:$D$104,MATCH(A21,Matières!$A$5:$A$104,0)),"introuvable")) | C21: =IF(A21="","",IFERROR(INDEX(Matières!$E$5:$E$104,MATCH(A21,Matières!$A$5:$A$104,0)),"introuvable")) | E21: =IF(AND(ISNUMBER(C21),ISNUMBER(D21)),C21*D21,0) -> 0
A22: Total matières (avant perte) | E22: =SUM(E12:E21) -> 1.177
A23: =IF(SUMPRODUCT((A12:A21<>"")*(1-ISNUMBER(C12:C21)))>0,"ATTENTION : une ligne n'a pas de coût unitaire (onglet Matières : prix et quantité du lot, ou nom modifié). Elle compte pour 0 €.","")
A24: Emballage et consommables
A25: Emballage / consommable | B25: Unité | C25: Coût unitaire | D25: Quantité utilisée | E25: Coût
A26: Pochette et carte bijou | B26: =IF(A26="","",IFERROR(INDEX(Matières!$D$5:$D$104,MATCH(A26,Matières!$A$5:$A$104,0)),"introuvable")) -> pièce | C26: =IF(A26="","",IFERROR(INDEX(Matières!$E$5:$E$104,MATCH(A26,Matières!$A$5:$A$104,0)),"introuvable")) -> 0.5 | D26: 1 | E26: =IF(AND(ISNUMBER(C26),ISNUMBER(D26)),C26*D26,0) -> 0.5
B27: =IF(A27="","",IFERROR(INDEX(Matières!$D$5:$D$104,MATCH(A27,Matières!$A$5:$A$104,0)),"introuvable")) | C27: =IF(A27="","",IFERROR(INDEX(Matières!$E$5:$E$104,MATCH(A27,Matières!$A$5:$A$104,0)),"introuvable")) | E27: =IF(AND(ISNUMBER(C27),ISNUMBER(D27)),C27*D27,0) -> 0
B28: =IF(A28="","",IFERROR(INDEX(Matières!$D$5:$D$104,MATCH(A28,Matières!$A$5:$A$104,0)),"introuvable")) | C28: =IF(A28="","",IFERROR(INDEX(Matières!$E$5:$E$104,MATCH(A28,Matières!$A$5:$A$104,0)),"introuvable")) | E28: =IF(AND(ISNUMBER(C28),ISNUMBER(D28)),C28*D28,0) -> 0
B29: =IF(A29="","",IFERROR(INDEX(Matières!$D$5:$D$104,MATCH(A29,Matières!$A$5:$A$104,0)),"introuvable")) | C29: =IF(A29="","",IFERROR(INDEX(Matières!$E$5:$E$104,MATCH(A29,Matières!$A$5:$A$104,0)),"introuvable")) | E29: =IF(AND(ISNUMBER(C29),ISNUMBER(D29)),C29*D29,0) -> 0
B30: =IF(A30="","",IFERROR(INDEX(Matières!$D$5:$D$104,MATCH(A30,Matières!$A$5:$A$104,0)),"introuvable")) | C30: =IF(A30="","",IFERROR(INDEX(Matières!$E$5:$E$104,MATCH(A30,Matières!$A$5:$A$104,0)),"introuvable")) | E30: =IF(AND(ISNUMBER(C30),ISNUMBER(D30)),C30*D30,0) -> 0
A31: Total emballage | E31: =SUM(E26:E30) -> 0.5
A32: =IF(SUMPRODUCT((A26:A30<>"")*(1-ISNUMBER(C26:C30)))>0,"ATTENTION : une ligne n'a pas de coût unitaire (onglet Matières : prix et quantité du lot, ou nom modifié). Elle compte pour 0 €.","")
A33: Coût de revient par produit
A34: Matières, perte incluse | B34: =IF(B5<1,E22/(1-B5),E22) -> 1.2134021 | C34: Calcul : total matières ÷ (1 − perte)
A35: Emballage et consommables | B35: =E31 -> 0.5
A36: Main-d'œuvre | B36: =IF(ISNUMBER(B6),B6/60*Paramètres!$C$10,0) -> 7.5 | C36: Calcul : minutes ÷ 60 × tarif horaire
A37: Part des frais fixes | B37: =Paramètres!$C$14 -> 1.5 | C37: Calcul : frais fixes mensuels ÷ produits vendus par mois
A38: COÛT DE REVIENT | B38: =SUM(B34:B37) -> 10.713402 | C38: Ce que vous coûte un produit, votre temps compris.
A39: Bénéfice visé | B39: =B38*B4 -> 4.2853608 | C39: Calcul : coût de revient × bénéfice visé %
A40: NET VISÉ PAR VENTE | B40: =B38+B39 -> 14.998763 | C40: Ce qui doit vous rester après frais, commissions, TVA et cotisations.
A42: Prix par canal de vente (TTC si vous facturez la TVA ; prix de gros : HT)
B43: Vente directe | C43: Etsy | D43: Dépôt-vente | E43: Gros (HT)
...

Sheet Fiche 3
A1: ="Fiche 3 : "&IF(B3="","(produit à nommer)",B3) -> Fiche 3 : Figurine imprimée en 3D
A3: Nom du produit | B3: Figurine imprimée en 3D
A4: Bénéfice visé (% du coût de revient) | B4: 0.35 | C4: Coefficient équivalent = 1 + % : | E4: =1+B4 -> 1.35
A5: Taux de perte ou d'échec (sur les matières) | B5: 0.1 | C5: Matières ÷ (1 − perte). Strictement inférieur à 100 %.
A6: Temps de fabrication par produit (minutes) | B6: 10 | C6: Multiplié par le tarif horaire des Paramètres.
A7: Livraison facturée au client (Etsy, €) | B7: 0 | C7: Payé par l'acheteur pour la livraison (soumis aux frais Etsy et aux cotisations).
A8: Coût d'envoi réel (Etsy, €) | B8: 0 | C8: Ce que l'envoi vous coûte réellement (timbre, transporteur).
A10: Matières utilisées (choisissez dans la liste, issue de l'onglet Matières)
A11: Matière | B11: Unité | C11: Coût unitaire | D11: Quantité utilisée | E11: Coût
A12: Filament PLA | B12: =IF(A12="","",IFERROR(INDEX(Matières!$D$5:$D$104,MATCH(A12,Matières!$A$5:$A$104,0)),"introuvable")) -> g | C12: =IF(A12="","",IFERROR(INDEX(Matières!$E$5:$E$104,MATCH(A12,Matières!$A$5:$A$104,0)),"introuvable")) -> 0.02 | D12: 50 | E12: =IF(AND(ISNUMBER(C12),ISNUMBER(D12)),C12*D12,0) -> 1
A13: Électricité | B13: =IF(A13="","",IFERROR(INDEX(Matières!$D$5:$D$104,MATCH(A13,Matières!$A$5:$A$104,0)),"introuvable")) -> kWh | C13: =IF(A13="","",IFERROR(INDEX(Matières!$E$5:$E$104,MATCH(A13,Matières!$A$5:$A$104,0)),"introuvable")) -> 0.2001 | D13: 0.3 | E13: =IF(AND(ISNUMBER(C13),ISNUMBER(D13)),C13*D13,0) -> 0.06003
A14: Amortissement imprimante 3D | B14: =IF(A14="","",IFERROR(INDEX(Matières!$D$5:$D$104,MATCH(A14,Matières!$A$5:$A$104,0)),"introuvable")) -> heure | C14: =IF(A14="","",IFERROR(INDEX(Matières!$E$5:$E$104,MATCH(A14,Matières!$A$5:$A$104,0)),"introuvable")) -> 0.09225 | D14: 3 | E14: =IF(AND(ISNUMBER(C14),ISNUMBER(D14)),C14*D14,0) -> 0.27675
B15: =IF(A15="","",IFERROR(INDEX(Matières!$D$5:$D$104,MATCH(A15,Matières!$A$5:$A$104,0)),"introuvable")) | C15: =IF(A15="","",IFERROR(INDEX(Matières!$E$5:$E$104,MATCH(A15,Matières!$A$5:$A$104,0)),"introuvable")) | E15: =IF(AND(ISNUMBER(C15),ISNUMBER(D15)),C15*D15,0) -> 0
B16: =IF(A16="","",IFERROR(INDEX(Matières!$D$5:$D$104,MATCH(A16,Matières!$A$5:$A$104,0)),"introuvable")) | C16: =IF(A16="","",IFERROR(INDEX(Matières!$E$5:$E$104,MATCH(A16,Matières!$A$5:$A$104,0)),"introuvable")) | E16: =IF(AND(ISNUMBER(C16),ISNUMBER(D16)),C16*D16,0) -> 0
B17: =IF(A17="","",IFERROR(INDEX(Matières!$D$5:$D$104,MATCH(A17,Matières!$A$5:$A$104,0)),"introuvable")) | C17: =IF(A17="","",IFERROR(INDEX(Matières!$E$5:$E$104,MATCH(A17,Matières!$A$5:$A$104,0)),"introuvable")) | E17: =IF(AND(ISNUMBER(C17),ISNUMBER(D17)),C17*D17,0) -> 0
B18: =IF(A18="","",IFERROR(INDEX(Matières!$D$5:$D$104,MATCH(A18,Matières!$A$5:$A$104,0)),"introuvable")) | C18: =IF(A18="","",IFERROR(INDEX(Matières!$E$5:$E$104,MATCH(A18,Matières!$A$5:$A$104,0)),"introuvable")) | E18: =IF(AND(ISNUMBER(C18),ISNUMBER(D18)),C18*D18,0) -> 0
B19: =IF(A19="","",IFERROR(INDEX(Matières!$D$5:$D$104,MATCH(A19,Matières!$A$5:$A$104,0)),"introuvable")) | C19: =IF(A19="","",IFERROR(INDEX(Matières!$E$5:$E$104,MATCH(A19,Matières!$A$5:$A$104,0)),"introuvable")) | E19: =IF(AND(ISNUMBER(C19),ISNUMBER(D19)),C19*D19,0) -> 0
B20: =IF(A20="","",IFERROR(INDEX(Matières!$D$5:$D$104,MATCH(A20,Matières!$A$5:$A$104,0)),"introuvable")) | C20: =IF(A20="","",IFERROR(INDEX(Matières!$E$5:$E$104,MATCH(A20,Matières!$A$5:$A$104,0)),"introuvable")) | E20: =IF(AND(ISNUMBER(C20),ISNUMBER(D20)),C20*D20,0) -> 0
B21: =IF(A21="","",IFERROR(INDEX(Matières!$D$5:$D$104,MATCH(A21,Matières!$A$5:$A$104,0)),"introuvable")) | C21: =IF(A21="","",IFERROR(INDEX(Matières!$E$5:$E$104,MATCH(A21,Matières!$A$5:$A$104,0)),"introuvable")) | E21: =IF(AND(ISNUMBER(C21),ISNUMBER(D21)),C21*D21,0) -> 0
A22: Total matières (avant perte) | E22: =SUM(E12:E21) -> 1.33678
A23: =IF(SUMPRODUCT((A12:A21<>"")*(1-ISNUMBER(C12:C21)))>0,"ATTENTION : une ligne n'a pas de coût unitaire (onglet Matières : prix et quantité du lot, ou nom modifié). Elle compte pour 0 €.","")
A24: Emballage et consommables
A25: Emballage / consommable | B25: Unité | C25: Coût unitaire | D25: Quantité utilisée | E25: Coût
A26: Boîte kraft | B26: =IF(A26="","",IFERROR(INDEX(Matières!$D$5:$D$104,MATCH(A26,Matières!$A$5:$A$104,0)),"introuvable")) -> pièce | C26: =IF(A26="","",IFERROR(INDEX(Matières!$E$5:$E$104,MATCH(A26,Matières!$A$5:$A$104,0)),"introuvable")) -> 0.4 | D26: 1 | E26: =IF(AND(ISNUMBER(C26),ISNUMBER(D26)),C26*D26,0) -> 0.4
A27: Papier de soie | B27: =IF(A27="","",IFERROR(INDEX(Matières!$D$5:$D$104,MATCH(A27,Matières!$A$5:$A$104,0)),"introuvable")) -> feuille | C27: =IF(A27="","",IFERROR(INDEX(Matières!$E$5:$E$104,MATCH(A27,Matières!$A$5:$A$104,0)),"introuvable")) -> 0.06 | D27: 1 | E27: =IF(AND(ISNUMBER(C27),ISNUMBER(D27)),C27*D27,0) -> 0.06
B28: =IF(A28="","",IFERROR(INDEX(Matières!$D$5:$D$104,MATCH(A28,Matières!$A$5:$A$104,0)),"introuvable")) | C28: =IF(A28="","",IFERROR(INDEX(Matières!$E$5:$E$104,MATCH(A28,Matières!$A$5:$A$104,0)),"introuvable")) | E28: =IF(AND(ISNUMBER(C28),ISNUMBER(D28)),C28*D28,0) -> 0
B29: =IF(A29="","",IFERROR(INDEX(Matières!$D$5:$D$104,MATCH(A29,Matières!$A$5:$A$104,0)),"introuvable")) | C29: =IF(A29="","",IFERROR(INDEX(Matières!$E$5:$E$104,MATCH(A29,Matières!$A$5:$A$104,0)),"introuvable")) | E29: =IF(AND(ISNUMBER(C29),ISNUMBER(D29)),C29*D29,0) -> 0
B30: =IF(A30="","",IFERROR(INDEX(Matières!$D$5:$D$104,MATCH(A30,Matières!$A$5:$A$104,0)),"introuvable")) | C30: =IF(A30="","",IFERROR(INDEX(Matières!$E$5:$E$104,MATCH(A30,Matières!$A$5:$A$104,0)),"introuvable")) | E30: =IF(AND(ISNUMBER(C30),ISNUMBER(D30)),C30*D30,0) -> 0
A31: Total emballage | E31: =SUM(E26:E30) -> 0.46
A32: =IF(SUMPRODUCT((A26:A30<>"")*(1-ISNUMBER(C26:C30)))>0,"ATTENTION : une ligne n'a pas de coût unitaire (onglet Matières : prix et quantité du lot, ou nom modifié). Elle compte pour 0 €.","")
A33: Coût de revient par produit
A34: Matières, perte incluse | B34: =IF(B5<1,E22/(1-B5),E22) -> 1.4853111 | C34: Calcul : total matières ÷ (1 − perte)
A35: Emballage et consommables | B35: =E31 -> 0.46
A36: Main-d'œuvre | B36: =IF(ISNUMBER(B6),B6/60*Paramètres!$C$10,0) -> 2.5 | C36: Calcul : minutes ÷ 60 × tarif horaire
A37: Part des frais fixes | B37: =Paramètres!$C$14 -> 1.5 | C37: Calcul : frais fixes mensuels ÷ produits vendus par mois
A38: COÛT DE REVIENT | B38: =SUM(B34:B37) -> 5.9453111 | C38: Ce que vous coûte un produit, votre temps compris.
A39: Bénéfice visé | B39: =B38*B4 -> 2.0808589 | C39: Calcul : coût de revient × bénéfice visé %
A40: NET VISÉ PAR VENTE | B40: =B38+B39 -> 8.02617 | C40: Ce qui doit vous rester après frais, commissions, TVA et cotisations.
A42: Prix par canal de vente (TTC si vous facturez la TVA ; prix de gros : HT)
B43: Vente directe | C43: Etsy | D43: Dépôt-vente | E43: Gros (HT)
...

Sheet Fiche 4
A1: ="Fiche 4 : "&IF(B3="","(produit à nommer)",B3) -> Fiche 4 : (produit à nommer)
A3: Nom du produit
A4: Bénéfice visé (% du coût de revient) | B4: 0.3 | C4: Coefficient équivalent = 1 + % : | E4: =1+B4 -> 1.3
A5: Taux de perte ou d'échec (sur les matières) | B5: 0 | C5: Matières ÷ (1 − perte). Strictement inférieur à 100 %.
A6: Temps de fabrication par produit (minutes) | C6: Multiplié par le tarif horaire des Paramètres.
A7: Livraison facturée au client (Etsy, €) | B7: 0 | C7: Payé par l'acheteur pour la livraison (soumis aux frais Etsy et aux cotisations).
A8: Coût d'envoi réel (Etsy, €) | B8: 0 | C8: Ce que l'envoi vous coûte réellement (timbre, transporteur).
A10: Matières utilisées (choisissez dans la liste, issue de l'onglet Matières)
A11: Matière | B11: Unité | C11: Coût unitaire | D11: Quantité utilisée | E11: Coût
B12: =IF(A12="","",IFERROR(INDEX(Matières!$D$5:$D$104,MATCH(A12,Matières!$A$5:$A$104,0)),"introuvable")) | C12: =IF(A12="","",IFERROR(INDEX(Matières!$E$5:$E$104,MATCH(A12,Matières!$A$5:$A$104,0)),"introuvable")) | E12: =IF(AND(ISNUMBER(C12),ISNUMBER(D12)),C12*D12,0) -> 0
B13: =IF(A13="","",IFERROR(INDEX(Matières!$D$5:$D$104,MATCH(A13,Matières!$A$5:$A$104,0)),"introuvable")) | C13: =IF(A13="","",IFERROR(INDEX(Matières!$E$5:$E$104,MATCH(A13,Matières!$A$5:$A$104,0)),"introuvable")) | E13: =IF(AND(ISNUMBER(C13),ISNUMBER(D13)),C13*D13,0) -> 0
B14: =IF(A14="","",IFERROR(INDEX(Matières!$D$5:$D$104,MATCH(A14,Matières!$A$5:$A$104,0)),"introuvable")) | C14: =IF(A14="","",IFERROR(INDEX(Matières!$E$5:$E$104,MATCH(A14,Matières!$A$5:$A$104,0)),"introuvable")) | E14: =IF(AND(ISNUMBER(C14),ISNUMBER(D14)),C14*D14,0) -> 0
B15: =IF(A15="","",IFERROR(INDEX(Matières!$D$5:$D$104,MATCH(A15,Matières!$A$5:$A$104,0)),"introuvable")) | C15: =IF(A15="","",IFERROR(INDEX(Matières!$E$5:$E$104,MATCH(A15,Matières!$A$5:$A$104,0)),"introuvable")) | E15: =IF(AND(ISNUMBER(C15),ISNUMBER(D15)),C15*D15,0) -> 0
B16: =IF(A16="","",IFERROR(INDEX(Matières!$D$5:$D$104,MATCH(A16,Matières!$A$5:$A$104,0)),"introuvable")) | C16: =IF(A16="","",IFERROR(INDEX(Matières!$E$5:$E$104,MATCH(A16,Matières!$A$5:$A$104,0)),"introuvable")) | E16: =IF(AND(ISNUMBER(C16),ISNUMBER(D16)),C16*D16,0) -> 0
B17: =IF(A17="","",IFERROR(INDEX(Matières!$D$5:$D$104,MATCH(A17,Matières!$A$5:$A$104,0)),"introuvable")) | C17: =IF(A17="","",IFERROR(INDEX(Matières!$E$5:$E$104,MATCH(A17,Matières!$A$5:$A$104,0)),"introuvable")) | E17: =IF(AND(ISNUMBER(C17),ISNUMBER(D17)),C17*D17,0) -> 0
B18: =IF(A18="","",IFERROR(INDEX(Matières!$D$5:$D$104,MATCH(A18,Matières!$A$5:$A$104,0)),"introuvable")) | C18: =IF(A18="","",IFERROR(INDEX(Matières!$E$5:$E$104,MATCH(A18,Matières!$A$5:$A$104,0)),"introuvable")) | E18: =IF(AND(ISNUMBER(C18),ISNUMBER(D18)),C18*D18,0) -> 0
B19: =IF(A19="","",IFERROR(INDEX(Matières!$D$5:$D$104,MATCH(A19,Matières!$A$5:$A$104,0)),"introuvable")) | C19: =IF(A19="","",IFERROR(INDEX(Matières!$E$5:$E$104,MATCH(A19,Matières!$A$5:$A$104,0)),"introuvable")) | E19: =IF(AND(ISNUMBER(C19),ISNUMBER(D19)),C19*D19,0) -> 0
B20: =IF(A20="","",IFERROR(INDEX(Matières!$D$5:$D$104,MATCH(A20,Matières!$A$5:$A$104,0)),"introuvable")) | C20: =IF(A20="","",IFERROR(INDEX(Matières!$E$5:$E$104,MATCH(A20,Matières!$A$5:$A$104,0)),"introuvable")) | E20: =IF(AND(ISNUMBER(C20),ISNUMBER(D20)),C20*D20,0) -> 0
B21: =IF(A21="","",IFERROR(INDEX(Matières!$D$5:$D$104,MATCH(A21,Matières!$A$5:$A$104,0)),"introuvable")) | C21: =IF(A21="","",IFERROR(INDEX(Matières!$E$5:$E$104,MATCH(A21,Matières!$A$5:$A$104,0)),"introuvable")) | E21: =IF(AND(ISNUMBER(C21),ISNUMBER(D21)),C21*D21,0) -> 0
A22: Total matières (avant perte) | E22: =SUM(E12:E21) -> 0
A23: =IF(SUMPRODUCT((A12:A21<>"")*(1-ISNUMBER(C12:C21)))>0,"ATTENTION : une ligne n'a pas de coût unitaire (onglet Matières : prix et quantité du lot, ou nom modifié). Elle compte pour 0 €.","")
A24: Emballage et consommables
A25: Emballage / consommable | B25: Unité | C25: Coût unitaire | D25: Quantité utilisée | E25: Coût
B26: =IF(A26="","",IFERROR(INDEX(Matières!$D$5:$D$104,MATCH(A26,Matières!$A$5:$A$104,0)),"introuvable")) | C26: =IF(A26="","",IFERROR(INDEX(Matières!$E$5:$E$104,MATCH(A26,Matières!$A$5:$A$104,0)),"introuvable")) | E26: =IF(AND(ISNUMBER(C26),ISNUMBER(D26)),C26*D26,0) -> 0
B27: =IF(A27="","",IFERROR(INDEX(Matières!$D$5:$D$104,MATCH(A27,Matières!$A$5:$A$104,0)),"introuvable")) | C27: =IF(A27="","",IFERROR(INDEX(Matières!$E$5:$E$104,MATCH(A27,Matières!$A$5:$A$104,0)),"introuvable")) | E27: =IF(AND(ISNUMBER(C27),ISNUMBER(D27)),C27*D27,0) -> 0
B28: =IF(A28="","",IFERROR(INDEX(Matières!$D$5:$D$104,MATCH(A28,Matières!$A$5:$A$104,0)),"introuvable")) | C28: =IF(A28="","",IFERROR(INDEX(Matières!$E$5:$E$104,MATCH(A28,Matières!$A$5:$A$104,0)),"introuvable")) | E28: =IF(AND(ISNUMBER(C28),ISNUMBER(D28)),C28*D28,0) -> 0
B29: =IF(A29="","",IFERROR(INDEX(Matières!$D$5:$D$104,MATCH(A29,Matières!$A$5:$A$104,0)),"introuvable")) | C29: =IF(A29="","",IFERROR(INDEX(Matières!$E$5:$E$104,MATCH(A29,Matières!$A$5:$A$104,0)),"introuvable")) | E29: =IF(AND(ISNUMBER(C29),ISNUMBER(D29)),C29*D29,0) -> 0
B30: =IF(A30="","",IFERROR(INDEX(Matières!$D$5:$D$104,MATCH(A30,Matières!$A$5:$A$104,0)),"introuvable")) | C30: =IF(A30="","",IFERROR(INDEX(Matières!$E$5:$E$104,MATCH(A30,Matières!$A$5:$A$104,0)),"introuvable")) | E30: =IF(AND(ISNUMBER(C30),ISNUMBER(D30)),C30*D30,0) -> 0
A31: Total emballage | E31: =SUM(E26:E30) -> 0
A32: =IF(SUMPRODUCT((A26:A30<>"")*(1-ISNUMBER(C26:C30)))>0,"ATTENTION : une ligne n'a pas de coût unitaire (onglet Matières : prix et quantité du lot, ou nom modifié). Elle compte pour 0 €.","")
A33: Coût de revient par produit
A34: Matières, perte incluse | B34: =IF(B5<1,E22/(1-B5),E22) -> 0 | C34: Calcul : total matières ÷ (1 − perte)
A35: Emballage et consommables | B35: =E31 -> 0
A36: Main-d'œuvre | B36: =IF(ISNUMBER(B6),B6/60*Paramètres!$C$10,0) -> 0 | C36: Calcul : minutes ÷ 60 × tarif horaire
A37: Part des frais fixes | B37: =Paramètres!$C$14 -> 1.5 | C37: Calcul : frais fixes mensuels ÷ produits vendus par mois
A38: COÛT DE REVIENT | B38: =SUM(B34:B37) -> 1.5 | C38: Ce que vous coûte un produit, votre temps compris.
A39: Bénéfice visé | B39: =B38*B4 -> 0.45 | C39: Calcul : coût de revient × bénéfice visé %
A40: NET VISÉ PAR VENTE | B40: =B38+B39 -> 1.95 | C40: Ce qui doit vous rester après frais, commissions, TVA et cotisations.
A42: Prix par canal de vente (TTC si vous facturez la TVA ; prix de gros : HT)
B43: Vente directe | C43: Etsy | D43: Dépôt-vente | E43: Gros (HT)
...

Sheet Synthèse
A1: Synthèse de tous les produits
A2: Tableau calculé automatiquement à partir des fiches produit. Prix TTC si TVA activée ; prix de gros en HT.
A4: Fiche | B4: Produit | C4: Coût de revient | D4: Net visé | E4: Prix min. vente directe | F4: Prix conseillé vente directe | G4: Prix conseillé Etsy | H4: Prix conseillé dépôt-vente | I4: Prix de gros HT | J4: Prix public conseillé | K4: Prix public boutique sans perte | L4: Prix public boutique avec bénéfice visé | M4: Net restant vente directe | N4: Net restant Etsy | O4: Net restant dépôt-vente | P4: Net restant gros | Q4: Bénéfice réel gros | R4: Alerte gros
A5: Fiche 1 | B5: =IF('Fiche 1'!B3="","(vide)",'Fiche 1'!B3) -> Bougie parfumée en pot 200 ml | C5: =IF(AND('Fiche 1'!$B$3="",'Fiche 1'!$E$22=0,'Fiche 1'!$E$31=0,N('Fiche 1'!$B$6)=0),"",'Fiche 1'!B38) -> 11.638333 | D5: =IF(AND('Fiche 1'!$B$3="",'Fiche 1'!$E$22=0,'Fiche 1'!$E$31=0,N('Fiche 1'!$B$6)=0),"",'Fiche 1'!B40) -> 15.129833 | E5: =IF(AND('Fiche 1'!$B$3="",'Fiche 1'!$E$22=0,'Fiche 1'!$E$31=0,N('Fiche 1'!$B$6)=0),"",'Fiche 1'!B49) -> 13.27062 | F5: =IF(AND('Fiche 1'!$B$3="",'Fiche 1'!$E$22=0,'Fiche 1'!$E$31=0,N('Fiche 1'!$B$6)=0),"",'Fiche 1'!B50) -> 17.251805 | G5: =IF(AND('Fiche 1'!$B$3="",'Fiche 1'!$E$22=0,'Fiche 1'!$E$31=0,N('Fiche 1'!$B$6)=0),"",'Fiche 1'!C50) -> À renseigner | H5: =IF(AND('Fiche 1'!$B$3="",'Fiche 1'!$E$22=0,'Fiche 1'!$E$31=0,N('Fiche 1'!$B$6)=0),"",'Fiche 1'!D50) -> 26.221548 | I5: =IF(AND('Fiche 1'!$B$3="",'Fiche 1'!$E$22=0,'Fiche 1'!$E$31=0,N('Fiche 1'!$B$6)=0),"",'Fiche 1'!E50) -> 7.8417297 | J5: =IF(AND('Fiche 1'!$B$3="",'Fiche 1'!$E$22=0,'Fiche 1'!$E$31=0,N('Fiche 1'!$B$6)=0),"",'Fiche 1'!E51) -> 17.251805 | K5: =IF(AND('Fiche 1'!$B$3="",'Fiche 1'!$E$22=0,'Fiche 1'!$E$31=0,N('Fiche 1'!$B$6)=0),"",'Fiche 1'!E52) -> 29.195363 | L5: =IF(AND('Fiche 1'!$B$3="",'Fiche 1'!$E$22=0,'Fiche 1'!$E$31=0,N('Fiche 1'!$B$6)=0),"",'Fiche 1'!E53) -> 37.953972 | M5: =IF(AND('Fiche 1'!$B$3="",'Fiche 1'!$E$22=0,'Fiche 1'!$E$31=0,N('Fiche 1'!$B$6)=0),"",'Fiche 1'!B61) -> 15.129833 | N5: =IF(AND('Fiche 1'!$B$3="",'Fiche 1'!$E$22=0,'Fiche 1'!$E$31=0,N('Fiche 1'!$B$6)=0),"",'Fiche 1'!C61) -> À renseigner | O5: =IF(AND('Fiche 1'!$B$3="",'Fiche 1'!$E$22=0,'Fiche 1'!$E$31=0,N('Fiche 1'!$B$6)=0),"",'Fiche 1'!D61) -> 15.129833 | P5: =IF(AND('Fiche 1'!$B$3="",'Fiche 1'!$E$22=0,'Fiche 1'!$E$31=0,N('Fiche 1'!$B$6)=0),"",'Fiche 1'!E61) -> 6.877197 | Q5: =IF(AND('Fiche 1'!$B$3="",'Fiche 1'!$E$22=0,'Fiche 1'!$E$31=0,N('Fiche 1'!$B$6)=0),"",'Fiche 1'!E62) -> -4.7611364 | R5: =IF(AND('Fiche 1'!$B$3="",'Fiche 1'!$E$22=0,'Fiche 1'!$E$31=0,N('Fiche 1'!$B$6)=0),"",'Fiche 1'!E63) -> ATTENTION : prix de gros à perte, vous perdez de l'argent sur chaque vente (ligne 62). Montez votre prix public (ligne 52 ou 53). | S5: =IF(AND('Fiche 1'!$B$3="",'Fiche 1'!$E$22=0,'Fiche 1'!$E$31=0,N('Fiche 1'!$B$6)=0),"",IF('Fiche 1'!A23&'Fiche 1'!A32<>"","ATTENTION : une matière n'a pas de coût","OK")) -> OK
A6: Fiche 2 | B6: =IF('Fiche 2'!B3="","(vide)",'Fiche 2'!B3) -> Bracelet chaîne et perles | C6: =IF(AND('Fiche 2'!$B$3="",'Fiche 2'!$E$22=0,'Fiche 2'!$E$31=0,N('Fiche 2'!$B$6)=0),"",'Fiche 2'!B38) -> 10.713402 | D6: =IF(AND('Fiche 2'!$B$3="",'Fiche 2'!$E$22=0,'Fiche 2'!$E$31=0,N('Fiche 2'!$B$6)=0),"",'Fiche 2'!B40) -> 14.998763 | E6: =IF(AND('Fiche 2'!$B$3="",'Fiche 2'!$E$22=0,'Fiche 2'!$E$31=0,N('Fiche 2'!$B$6)=0),"",'Fiche 2'!B49) -> 12.215966 | F6: =IF(AND('Fiche 2'!$B$3="",'Fiche 2'!$E$22=0,'Fiche 2'!$E$31=0,N('Fiche 2'!$B$6)=0),"",'Fiche 2'!B50) -> 17.102352 | G6: =IF(AND('Fiche 2'!$B$3="",'Fiche 2'!$E$22=0,'Fiche 2'!$E$31=0,N('Fiche 2'!$B$6)=0),"",'Fiche 2'!C50) -> À renseigner | H6: =IF(AND('Fiche 2'!$B$3="",'Fiche 2'!$E$22=0,'Fiche 2'!$E$31=0,N('Fiche 2'!$B$6)=0),"",'Fiche 2'!D50) -> 25.99439 | I6: =IF(AND('Fiche 2'!$B$3="",'Fiche 2'!$E$22=0,'Fiche 2'!$E$31=0,N('Fiche 2'!$B$6)=0),"",'Fiche 2'!E50) -> 7.7737965 | J6: =IF(AND('Fiche 2'!$B$3="",'Fiche 2'!$E$22=0,'Fiche 2'!$E$31=0,N('Fiche 2'!$B$6)=0),"",'Fiche 2'!E51) -> 17.102352 | K6: =IF(AND('Fiche 2'!$B$3="",'Fiche 2'!$E$22=0,'Fiche 2'!$E$31=0,N('Fiche 2'!$B$6)=0),"",'Fiche 2'!E52) -> 26.875125 | L6: =IF(AND('Fiche 2'!$B$3="",'Fiche 2'!$E$22=0,'Fiche 2'!$E$31=0,N('Fiche 2'!$B$6)=0),"",'Fiche 2'!E53) -> 37.625175 | M6: =IF(AND('Fiche 2'!$B$3="",'Fiche 2'!$E$22=0,'Fiche 2'!$E$31=0,N('Fiche 2'!$B$6)=0),"",'Fiche 2'!B61) -> 14.998763 | N6: =IF(AND('Fiche 2'!$B$3="",'Fiche 2'!$E$22=0,'Fiche 2'!$E$31=0,N('Fiche 2'!$B$6)=0),"",'Fiche 2'!C61) -> À renseigner | O6: =IF(AND('Fiche 2'!$B$3="",'Fiche 2'!$E$22=0,'Fiche 2'!$E$31=0,N('Fiche 2'!$B$6)=0),"",'Fiche 2'!D61) -> 14.998763 | P6: =IF(AND('Fiche 2'!$B$3="",'Fiche 2'!$E$22=0,'Fiche 2'!$E$31=0,N('Fiche 2'!$B$6)=0),"",'Fiche 2'!E61) -> 6.8176195 | Q6: =IF(AND('Fiche 2'!$B$3="",'Fiche 2'!$E$22=0,'Fiche 2'!$E$31=0,N('Fiche 2'!$B$6)=0),"",'Fiche 2'!E62) -> -3.8957826 | R6: =IF(AND('Fiche 2'!$B$3="",'Fiche 2'!$E$22=0,'Fiche 2'!$E$31=0,N('Fiche 2'!$B$6)=0),"",'Fiche 2'!E63) -> ATTENTION : prix de gros à perte, vous perdez de l'argent sur chaque vente (ligne 62). Montez votre prix public (ligne 52 ou 53). | S6: =IF(AND('Fiche 2'!$B$3="",'Fiche 2'!$E$22=0,'Fiche 2'!$E$31=0,N('Fiche 2'!$B$6)=0),"",IF('Fiche 2'!A23&'Fiche 2'!A32<>"","ATTENTION : une matière n'a pas de coût","OK")) -> OK
A7: Fiche 3 | B7: =IF('Fiche 3'!B3="","(vide)",'Fiche 3'!B3) -> Figurine imprimée en 3D | C7: =IF(AND('Fiche 3'!$B$3="",'Fiche 3'!$E$22=0,'Fiche 3'!$E$31=0,N('Fiche 3'!$B$6)=0),"",'Fiche 3'!B38) -> 5.9453111 | D7: =IF(AND('Fiche 3'!$B$3="",'Fiche 3'!$E$22=0,'Fiche 3'!$E$31=0,N('Fiche 3'!$B$6)=0),"",'Fiche 3'!B40) -> 8.02617 | E7: =IF(AND('Fiche 3'!$B$3="",'Fiche 3'!$E$22=0,'Fiche 3'!$E$31=0,N('Fiche 3'!$B$6)=0),"",'Fiche 3'!B49) -> 6.7791461 | F7: =IF(AND('Fiche 3'!$B$3="",'Fiche 3'!$E$22=0,'Fiche 3'!$E$31=0,N('Fiche 3'!$B$6)=0),"",'Fiche 3'!B50) -> 9.1518472 | G7: =IF(AND('Fiche 3'!$B$3="",'Fiche 3'!$E$22=0,'Fiche 3'!$E$31=0,N('Fiche 3'!$B$6)=0),"",'Fiche 3'!C50) -> À renseigner | H7: =IF(AND('Fiche 3'!$B$3="",'Fiche 3'!$E$22=0,'Fiche 3'!$E$31=0,N('Fiche 3'!$B$6)=0),"",'Fiche 3'!D50) -> 13.910173 | I7: =IF(AND('Fiche 3'!$B$3="",'Fiche 3'!$E$22=0,'Fiche 3'!$E$31=0,N('Fiche 3'!$B$6)=0),"",'Fiche 3'!E50) -> 4.1599305 | J7: =IF(AND('Fiche 3'!$B$3="",'Fiche 3'!$E$22=0,'Fiche 3'!$E$31=0,N('Fiche 3'!$B$6)=0),"",'Fiche 3'!E51) -> 9.1518472 | K7: =IF(AND('Fiche 3'!$B$3="",'Fiche 3'!$E$22=0,'Fiche 3'!$E$31=0,N('Fiche 3'!$B$6)=0),"",'Fiche 3'!E52) -> 14.914121 | L7: =IF(AND('Fiche 3'!$B$3="",'Fiche 3'!$E$22=0,'Fiche 3'!$E$31=0,N('Fiche 3'!$B$6)=0),"",'Fiche 3'!E53) -> 20.134064 | M7: =IF(AND('Fiche 3'!$B$3="",'Fiche 3'!$E$22=0,'Fiche 3'!$E$31=0,N('Fiche 3'!$B$6)=0),"",'Fiche 3'!B61) -> 8.02617 | N7: =IF(AND('Fiche 3'!$B$3="",'Fiche 3'!$E$22=0,'Fiche 3'!$E$31=0,N('Fiche 3'!$B$6)=0),"",'Fiche 3'!C61) -> À renseigner | O7: =IF(AND('Fiche 3'!$B$3="",'Fiche 3'!$E$22=0,'Fiche 3'!$E$31=0,N('Fiche 3'!$B$6)=0),"",'Fiche 3'!D61) -> 8.02617 | P7: =IF(AND('Fiche 3'!$B$3="",'Fiche 3'!$E$22=0,'Fiche 3'!$E$31=0,N('Fiche 3'!$B$6)=0),"",'Fiche 3'!E61) -> 3.6482591 | Q7: =IF(AND('Fiche 3'!$B$3="",'Fiche 3'!$E$22=0,'Fiche 3'!$E$31=0,N('Fiche 3'!$B$6)=0),"",'Fiche 3'!E62) -> -2.297052 | R7: =IF(AND('Fiche 3'!$B$3="",'Fiche 3'!$E$22=0,'Fiche 3'!$E$31=0,N('Fiche 3'!$B$6)=0),"",'Fiche 3'!E63) -> ATTENTION : prix de gros à perte, vous perdez de l'argent sur chaque vente (ligne 62). Montez votre prix public (ligne 52 ou 53). | S7: =IF(AND('Fiche 3'!$B$3="",'Fiche 3'!$E$22=0,'Fiche 3'!$E$31=0,N('Fiche 3'!$B$6)=0),"",IF('Fiche 3'!A23&'Fiche 3'!A32<>"","ATTENTION : une matière n'a pas de coût","OK")) -> OK
A8: Fiche 4 | B8: =IF('Fiche 4'!B3="","(vide)",'Fiche 4'!B3) -> (vide) | C8: =IF(AND('Fiche 4'!$B$3="",'Fiche 4'!$E$22=0,'Fiche 4'!$E$31=0,N('Fiche 4'!$B$6)=0),"",'Fiche 4'!B38) | D8: =IF(AND('Fiche 4'!$B$3="",'Fiche 4'!$E$22=0,'Fiche 4'!$E$31=0,N('Fiche 4'!$B$6)=0),"",'Fiche 4'!B40) | E8: =IF(AND('Fiche 4'!$B$3="",'Fiche 4'!$E$22=0,'Fiche 4'!$E$31=0,N('Fiche 4'!$B$6)=0),"",'Fiche 4'!B49) | F8: =IF(AND('Fiche 4'!$B$3="",'Fiche 4'!$E$22=0,'Fiche 4'!$E$31=0,N('Fiche 4'!$B$6)=0),"",'Fiche 4'!B50) | G8: =IF(AND('Fiche 4'!$B$3="",'Fiche 4'!$E$22=0,'Fiche 4'!$E$31=0,N('Fiche 4'!$B$6)=0),"",'Fiche 4'!C50) | H8: =IF(AND('Fiche 4'!$B$3="",'Fiche 4'!$E$22=0,'Fiche 4'!$E$31=0,N('Fiche 4'!$B$6)=0),"",'Fiche 4'!D50) | I8: =IF(AND('Fiche 4'!$B$3="",'Fiche 4'!$E$22=0,'Fiche 4'!$E$31=0,N('Fiche 4'!$B$6)=0),"",'Fiche 4'!E50) | J8: =IF(AND('Fiche 4'!$B$3="",'Fiche 4'!$E$22=0,'Fiche 4'!$E$31=0,N('Fiche 4'!$B$6)=0),"",'Fiche 4'!E51) | K8: =IF(AND('Fiche 4'!$B$3="",'Fiche 4'!$E$22=0,'Fiche 4'!$E$31=0,N('Fiche 4'!$B$6)=0),"",'Fiche 4'!E52) | L8: =IF(AND('Fiche 4'!$B$3="",'Fiche 4'!$E$22=0,'Fiche 4'!$E$31=0,N('Fiche 4'!$B$6)=0),"",'Fiche 4'!E53) | M8: =IF(AND('Fiche 4'!$B$3="",'Fiche 4'!$E$22=0,'Fiche 4'!$E$31=0,N('Fiche 4'!$B$6)=0),"",'Fiche 4'!B61) | N8: =IF(AND('Fiche 4'!$B$3="",'Fiche 4'!$E$22=0,'Fiche 4'!$E$31=0,N('Fiche 4'!$B$6)=0),"",'Fiche 4'!C61) | O8: =IF(AND('Fiche 4'!$B$3="",'Fiche 4'!$E$22=0,'Fiche 4'!$E$31=0,N('Fiche 4'!$B$6)=0),"",'Fiche 4'!D61) | P8: =IF(AND('Fiche 4'!$B$3="",'Fiche 4'!$E$22=0,'Fiche 4'!$E$31=0,N('Fiche 4'!$B$6)=0),"",'Fiche 4'!E61) | Q8: =IF(AND('Fiche 4'!$B$3="",'Fiche 4'!$E$22=0,'Fiche 4'!$E$31=0,N('Fiche 4'!$B$6)=0),"",'Fiche 4'!E62) | R8: =IF(AND('Fiche 4'!$B$3="",'Fiche 4'!$E$22=0,'Fiche 4'!$E$31=0,N('Fiche 4'!$B$6)=0),"",'Fiche 4'!E63) | S8: =IF(AND('Fiche 4'!$B$3="",'Fiche 4'!$E$22=0,'Fiche 4'!$E$31=0,N('Fiche 4'!$B$6)=0),"",IF('Fiche 4'!A23&'Fiche 4'!A32<>"","ATTENTION : une matière n'a pas de coût","OK"))
